tests/fixtures/binance/synthetic_diff_updates.jsonl
{"e": "depthUpdate", "E": 1700000001000, "T": 1700000001000, "s": "TESTUSDT", "U": 101, "u": 105, "pu": 100, "b": [["100.00", "1.25"]], "a": []}
{"e": "depthUpdate", "E": 1700000002000, "T": 1700000002000, "s": "TESTUSDT", "U": 106, "u": 110, "pu": 105, "b": [["99.00", "0"]], "a": [["100.50", "2.00"]]}
{"e": "depthUpdate", "E": 1700000003000, "T": 1700000003000, "s": "TESTUSDT", "U": 111, "u": 115, "pu": 110, "b": [["98.50", "4.00"]], "a": [["101.75", "1.00"]]}
