tests/fixtures/binance/synthetic_stale_updates.jsonl
{"e": "depthUpdate", "E": 1700000000500, "T": 1700000000500, "s": "TESTUSDT", "U": 95, "u": 98, "pu": 90, "b": [["99.50", "5.00"]], "a": []}
{"e": "depthUpdate", "E": 1700000000800, "T": 1700000000800, "s": "TESTUSDT", "U": 99, "u": 100, "pu": 98, "b": [["99.00", "5.00"]], "a": []}
{"e": "depthUpdate", "E": 1700000001000, "T": 1700000001000, "s": "TESTUSDT", "U": 101, "u": 105, "pu": 100, "b": [["100.00", "1.25"]], "a": []}
{"e": "depthUpdate", "E": 1700000002000, "T": 1700000002000, "s": "TESTUSDT", "U": 106, "u": 110, "pu": 105, "b": [["99.00", "0"]], "a": [["100.50", "2.00"]]}
