tests/fixtures/fi2010/tiny_fi2010_like.csv
timestamp,split,bid_price_1,bid_quantity_1,ask_price_1,ask_quantity_1,bid_price_2,bid_quantity_2,ask_price_2,ask_quantity_2,label_10,label_50,label_100
2024-01-02T09:30:00+00:00,train,99.50,10,100.50,12,99.40,8,100.60,15,1,1,2
2024-01-02T09:30:01+00:00,train,99.55,11,100.55,13,99.45,9,100.65,16,1,2,2
2024-01-02T09:30:02+00:00,train,99.45,9,100.45,11,99.35,7,100.55,14,2,2,3
2024-01-02T09:30:03+00:00,train,99.60,12,100.60,14,99.50,10,100.70,17,1,1,1
2024-01-02T09:30:04+00:00,test,99.40,8,100.40,10,99.30,6,100.50,13,3,3,2
2024-01-02T09:30:05+00:00,test,99.35,7,100.35,9,99.25,5,100.45,12,2,3,3
